<?xml version="1.0" ?>
<!-- =================================================================================== -->
<!-- |    This document was autogenerated by xacro from jetarm_6dof_robot.urdf.xacro   | -->
<!-- |    EDITING THIS FILE BY HAND IS NOT RECOMMENDED                                 | -->
<!-- =================================================================================== -->
<robot name="jetarm_6dof">
  <material name="black">
    <color rgba="0.3 0.3 0.3 1.0"/>
  </material>
  <material name="blue">
    <color rgba="0.0 0.0 0.8 1.0"/>
  </material>
  <material name="green">
    <color rgba="0.3 0.6 0.3 1.0"/>
  </material>
  <material name="gray">
    <color rgba="0.7 0.7 0.7 1.0"/>
  </material>
  <material name="darkgray">
    <color rgba="0.3 0.3 0.3 1.0"/>
  </material>
  <material name="red">
    <color rgba="0.8 0.0 0.0 1.0"/>
  </material>
  <material name="white">
    <color rgba="1.0 1.0 1.0 1.0"/>
  </material>
  <material name="yellow">
    <color rgba="0.8 0.8 0.0 1.0"/>
  </material>
  <!-- Used for fixing robot -->
  <link name="world"/>
  <gazebo reference="world">
    <static>true</static>
  </gazebo>
  <joint name="base_joint" type="fixed">
    <parent link="world"/>
    <child link="base_link"/>
  </joint>
  <link name="base_link">
    <visual>
      <origin rpy="0.0 0.0 -1.5707963267948966" xyz="0.0 0.0 0.0"/>
      <geometry>
        <mesh filename="package://jetarm_6dof_description/meshes/jetarm_6dof/JetArm_6DOF_BASE_GREEN.STL" scale="0.001 0.001 0.001"/>
      </geometry>
      <material name="jetarm_green">
        <color rgba="0.4 0.9 0.4 1.0"/>
      </material>
    </visual>
    <visual>
      <origin rpy="0.0 0.0 -1.5707963267948966" xyz="0.0 0.0 0.0"/>
      <geometry>
        <mesh filename="package://jetarm_6dof_description/meshes/jetarm_6dof/JetArm_6DOF_BASE_BLACK.STL" scale="0.001 0.001 0.001"/>
      </geometry>
      <material name="black">
        <color rgba="0.15 0.15 0.15 1.0"/>
      </material>
    </visual>
    <visual>
      <origin rpy="0.0 0.0 -1.5707963267948966" xyz="0.0 0.0 0.0"/>
      <geometry>
        <mesh filename="package://jetarm_6dof_description/meshes/jetarm_6dof/JetArm_6DOF_BASE_SCREEN.STL" scale="0.001 0.001 0.001"/>
      </geometry>
      <material name="black">
        <color rgba="0.15 0.15 0.15 1.0"/>
      </material>
    </visual>
    <visual>
      <origin rpy="0.0 0.0 -1.5707963267948966" xyz="0.0 0.0 0.0"/>
      <geometry>
        <mesh filename="package://jetarm_6dof_description/meshes/jetarm_6dof/JetArm_6DOF_BASE_WHITE.STL" scale="0.001 0.001 0.001"/>
      </geometry>
      <material name="white">
        <color rgba="0.8 0.8 0.8 1.0"/>
      </material>
    </visual>
    <collision>
      <origin rpy="0.0 0.0 -1.5707963267948966" xyz="0.0 0.0 0.0"/>
      <geometry>
        <mesh filename="package://jetarm_6dof_description/meshes/jetarm_6dof/JetArm_6DOF_BASE.STL" scale="0.001 0.001 0.001"/>
      </geometry>
    </collision>
    <inertial>
      <origin rpy="0.0 0.0 -1.5707963267948966" xyz="0.0 0.0 0.0"/>
      <mass value="0.1"/>
      <inertia ixx="1.0" ixy="0.0" ixz="0.0" iyy="1.0" iyz="0.0" izz="1.0"/>
    </inertial>
  </link>
  <joint name="joint1" type="revolute">
    <parent link="base_link"/>
    <child link="link1"/>
    <origin rpy="0.0 0.0 0.0" xyz="0.0 0.0 0.10314916202"/>
    <limit effort="6.0" lower="-2.1" upper="2.1" velocity="0.524"/>
    <axis xyz="0 0 1"/>
  </joint>
  <link name="link1">
    <visual>
      <origin rpy="0.0 0.0 0.0" xyz="0.0 0.0 0.0"/>
      <geometry>
        <mesh filename="package://jetarm_6dof_description/meshes/jetarm_6dof/JetArm_6DOF_LINK1_BLACK.STL" scale="0.001 0.001 0.001"/>
      </geometry>
      <material name="black">
        <color rgba="0.15 0.15 0.15 1.0"/>
      </material>
    </visual>
    <visual>
      <origin rpy="0.0 0.0 0.0" xyz="0.0 0.0 0.0"/>
      <geometry>
        <mesh filename="package://jetarm_6dof_description/meshes/jetarm_6dof/JetArm_6DOF_LINK1_GREEN.STL" scale="0.001 0.001 0.001"/>
      </geometry>
      <material name="jetarm_green">
        <color rgba="0.4 0.9 0.4 1.0"/>
      </material>
    </visual>
    <collision>
      <origin rpy="0.0 0.0 0.0" xyz="0.0 0.0 0.0"/>
      <geometry>
        <mesh filename="package://jetarm_6dof_description/meshes/jetarm_6dof/JetArm_6DOF_LINK1.STL" scale="0.001 0.001 0.001"/>
      </geometry>
    </collision>
    <inertial>
      <origin rpy="0.0 0.0 0.0" xyz="0.0 0.0 0.0"/>
      <mass value="0.001"/>
      <inertia ixx="1.0" ixy="0.0" ixz="0.0" iyy="1.0" iyz="0.0" izz="1.0"/>
    </inertial>
  </link>
  <joint name="joint2" type="revolute">
    <parent link="link1"/>
    <child link="link2"/>
    <origin rpy="1.5707963267948966 0.0 0.0" xyz="0.0 0.0 0.0"/>
    <limit effort="6.0" lower="-2.1" upper="2.1" velocity="0.524"/>
    <axis xyz="0 0 1"/>
  </joint>
  <link name="link2">
    <visual>
      <origin rpy="0.0 0.0 0.0" xyz="0.0 0.0 0.0"/>
      <geometry>
        <mesh filename="package://jetarm_6dof_description/meshes/jetarm_6dof/JetArm_6DOF_LINK2_GREEN.STL" scale="0.001 0.001 0.001"/>
      </geometry>
      <material name="jetarm_green">
        <color rgba="0.4 0.9 0.4 1.0"/>
      </material>
    </visual>
    <visual>
      <origin rpy="0.0 0.0 0.0" xyz="0.0 0.0 0.0"/>
      <geometry>
        <mesh filename="package://jetarm_6dof_description/meshes/jetarm_6dof/JetArm_6DOF_LINK2_WHITE.STL" scale="0.001 0.001 0.001"/>
      </geometry>
      <material name="white">
        <color rgba="0.8 0.8 0.8 1.0"/>
      </material>
    </visual>
    <visual>
      <origin rpy="0.0 0.0 0.0" xyz="0.0 0.0 0.0"/>
      <geometry>
        <mesh filename="package://jetarm_6dof_description/meshes/jetarm_6dof/JetArm_6DOF_LINK2_BLACK.STL" scale="0.001 0.001 0.001"/>
      </geometry>
      <material name="black">
        <color rgba="0.15 0.15 0.15 1.0"/>
      </material>
    </visual>
    <collision>
      <origin rpy="0.0 0.0 0.0" xyz="0.0 0.0 0.0"/>
      <geometry>
        <mesh filename="package://jetarm_6dof_description/meshes/jetarm_6dof/JetArm_6DOF_LINK2.STL" scale="0.001 0.001 0.001"/>
      </geometry>
    </collision>
    <inertial>
      <origin rpy="0.0 0.0 0.0" xyz="0.0 0.0 0.0"/>
      <mass value="0.001"/>
      <inertia ixx="1.0" ixy="0.0" ixz="0.0" iyy="1.0" iyz="0.0" izz="1.0"/>
    </inertial>
  </link>
  <joint name="joint3" type="revolute">
    <parent link="link2"/>
    <child link="link3"/>
    <origin rpy="0.0 0.0 0.0" xyz="0.0 0.12941763737 0.0"/>
    <limit effort="6.0" lower="-2.1" upper="2.1" velocity="0.524"/>
    <axis xyz="0 0 1"/>
  </joint>
  <link name="link3">
    <visual>
      <origin rpy="0.0 0.0 0.0" xyz="0.0 0.0 0.0"/>
      <geometry>
        <mesh filename="package://jetarm_6dof_description/meshes/jetarm_6dof/JetArm_6DOF_LINK3_GREEN.STL" scale="0.001 0.001 0.001"/>
      </geometry>
      <material name="jetarm_green">
        <color rgba="0.4 0.9 0.4 1.0"/>
      </material>
    </visual>
    <visual>
      <origin rpy="0.0 0.0 0.0" xyz="0.0 0.0 0.0"/>
      <geometry>
        <mesh filename="package://jetarm_6dof_description/meshes/jetarm_6dof/JetArm_6DOF_LINK3_WHITE.STL" scale="0.001 0.001 0.001"/>
      </geometry>
      <material name="white">
        <color rgba="0.8 0.8 0.8 1.0"/>
      </material>
    </visual>
    <visual>
      <origin rpy="0.0 0.0 0.0" xyz="0.0 0.0 0.0"/>
      <geometry>
        <mesh filename="package://jetarm_6dof_description/meshes/jetarm_6dof/JetArm_6DOF_LINK3_BLACK.STL" scale="0.001 0.001 0.001"/>
      </geometry>
      <material name="black">
        <color rgba="0.15 0.15 0.15 1.0"/>
      </material>
    </visual>
    <collision>
      <origin rpy="0.0 0.0 0.0" xyz="0.0 0.0 0.0"/>
      <geometry>
        <mesh filename="package://jetarm_6dof_description/meshes/jetarm_6dof/JetArm_6DOF_LINK3.STL" scale="0.001 0.001 0.001"/>
      </geometry>
    </collision>
    <inertial>
      <origin rpy="0.0 0.0 0.0" xyz="0.0 0.0 0.0"/>
      <mass value="0.001"/>
      <inertia ixx="1.0" ixy="0.0" ixz="0.0" iyy="1.0" iyz="0.0" izz="1.0"/>
    </inertial>
  </link>
  <joint name="joint4" type="revolute">
    <parent link="link3"/>
    <child link="link4"/>
    <origin rpy="0.0 0.0 0.0" xyz="0.0 0.12941763737 0.0"/>
    <limit effort="6.0" lower="-2.1" upper="2.1" velocity="0.524"/>
    <axis xyz="0 0 1"/>
  </joint>
  <link name="link4">
    <visual>
      <origin rpy="0.0 0.0 0.0" xyz="0.0 0.0 0.0"/>
      <geometry>
        <mesh filename="package://jetarm_6dof_description/meshes/jetarm_6dof/JetArm_6DOF_LINK4_GEMINI_GREEN.STL" scale="0.001 0.001 0.001"/>
      </geometry>
      <material name="jetarm_green">
        <color rgba="0.4 0.9 0.4 1.0"/>
      </material>
    </visual>
    <visual>
      <origin rpy="0.0 0.0 0.0" xyz="0.0 0.0 0.0"/>
      <geometry>
        <mesh filename="package://jetarm_6dof_description/meshes/jetarm_6dof/JetArm_6DOF_LINK4_GEMINI_WHITE.STL" scale="0.001 0.001 0.001"/>
      </geometry>
      <material name="white">
        <color rgba="0.8 0.8 0.8 1.0"/>
      </material>
    </visual>
    <visual>
      <origin rpy="0.0 0.0 0.0" xyz="0.0 0.0 0.0"/>
      <geometry>
        <mesh filename="package://jetarm_6dof_description/meshes/jetarm_6dof/JetArm_6DOF_LINK4_GEMINI_BLACK.STL" scale="0.001 0.001 0.001"/>
      </geometry>
      <material name="black">
        <color rgba="0.15 0.15 0.15 1.0"/>
      </material>
    </visual>
    <collision>
      <origin rpy="0.0 0.0 0.0" xyz="0.0 0.0 0.0"/>
      <geometry>
        <mesh filename="package://jetarm_6dof_description/meshes/jetarm_6dof/JetArm_6DOF_LINK4_GEMINI.STL" scale="0.001 0.001 0.001"/>
      </geometry>
    </collision>
    <inertial>
      <origin rpy="0.0 0.0 0.0" xyz="0.0 0.0 0.0"/>
      <mass value="0.001"/>
      <inertia ixx="1.0" ixy="0.0" ixz="0.0" iyy="1.0" iyz="0.0" izz="1.0"/>
    </inertial>
  </link>
  <joint name="joint5" type="revolute">
    <parent link="link4"/>
    <child link="link5"/>
    <origin rpy="-1.5707963267948966 0.0 0.0" xyz="0.0 0.05945312631 0.0"/>
    <limit effort="6.0" lower="-2.1" upper="2.1" velocity="0.524"/>
    <axis xyz="0 0 1"/>
  </joint>
  <link name="link5">
    <visual>
      <origin rpy="0.0 0.0 0.0" xyz="0.0 0.0 0.0"/>
      <geometry>
        <mesh filename="package://jetarm_6dof_description/meshes/jetarm_6dof/JetArm_6DOF_LINK5_WHITE.STL" scale="0.001 0.001 0.001"/>
      </geometry>
      <material name="white">
        <color rgba="0.8 0.8 0.8 1.0"/>
      </material>
    </visual>
    <collision>
      <origin rpy="0.0 0.0 0.0" xyz="0.0 0.0 0.0"/>
      <geometry>
        <mesh filename="package://jetarm_6dof_description/meshes/jetarm_6dof/JetArm_6DOF_LINK5.STL" scale="0.001 0.001 0.001"/>
      </geometry>
    </collision>
    <inertial>
      <origin rpy="0.0 0.0 0.0" xyz="0.0 0.0 0.0"/>
      <mass value="0.001"/>
      <inertia ixx="1.0" ixy="0.0" ixz="0.0" iyy="1.0" iyz="0.0" izz="1.0"/>
    </inertial>
  </link>
  <joint name="endpoint" type="fixed">
    <origin rpy="0 0 0" xyz="0 0 0.11054687369"/>
    <parent link="link5"/>
    <child link="endpoint"/>
    <axis xyz="0 0 0"/>
  </joint>
  <link name="endpoint"/>
  <link name="gripper_servo_link">
    <inertial>
      <origin rpy="0 0 0" xyz="0.00173398274658465 0.0143803550122597 0.0668818334351561"/>
      <mass value="0.0174988102544488"/>
      <inertia ixx="1.57024155329016E-06" ixy="2.76817630588513E-08" ixz="2.23194266007272E-08" iyy="4.12618454370932E-06" iyz="3.03828124784084E-10" izz="3.2611413740062E-06"/>
    </inertial>
    <visual>
      <origin rpy="0 0 0" xyz="0 0 0"/>
      <geometry>
        <mesh filename="package://jetarm_6dof_description/meshes/Gripper_Base.STL" scale="0.001 0.001 0.001"/>
      </geometry>
      <material name="black">
        <color rgba="0.15 0.15 0.15 1.0"/>
      </material>
    </visual>
    <collision>
      <origin rpy="0 0 0" xyz="0 0 0"/>
      <geometry>
        <mesh filename="package://jetarm_6dof_description/meshes/Gripper_Base.STL" scale="0.001 0.001 0.001"/>
      </geometry>
    </collision>
  </link>
  <joint name="gripper_servo_joint" type="fixed">
    <origin rpy="0 0 0" xyz="0 0 0"/>
    <parent link="link5"/>
    <child link="gripper_servo_link"/>
    <axis xyz="0 0 0"/>
  </joint>
  <link name="r_link">
    <inertial>
      <origin rpy="0 0 0" xyz="0.000541257829657527 -0.00150000000696238 0.00625150798228247"/>
      <mass value="0.00001"/>
      <inertia ixx="10" ixy="0" ixz="0" iyy="10" iyz="0" izz="10"/>
    </inertial>
    <visual>
      <origin rpy="0 0 0" xyz="0 0 0"/>
      <geometry>
        <mesh filename="package://jetarm_6dof_description/meshes/gripper/r_link.stl"/>
      </geometry>
      <material name="black"/>
    </visual>
    <collision>
      <origin rpy="0 0 0" xyz="0 0 0"/>
      <geometry>
        <mesh filename="package://jetarm_6dof_description/meshes/gripper/r_link.stl"/>
      </geometry>
    </collision>
  </link>
  <joint name="r_joint" type="revolute">
    <origin rpy="0 0 1.5707963267948966" xyz="-0.00704769 -0.01399984321 0.02700709328"/>
    <parent link="gripper_servo_link"/>
    <child link="r_link"/>
    <axis xyz="0 -1 0"/>
    <limit effort="1000" lower="0" upper="1.57" velocity="2"/>
  </joint>
  <link name="l_link">
    <inertial>
      <origin rpy="0 0 0" xyz="0.0054115 -0.0015023 0.0058059"/>
      <mass value="0.00001"/>
      <inertia ixx="10" ixy="0" ixz="0" iyy="10" iyz="0" izz="10"/>
    </inertial>
    <visual>
      <origin rpy="0 0 0" xyz="0 0 0"/>
      <geometry>
        <mesh filename="package://jetarm_6dof_description/meshes/gripper/l_link.stl"/>
      </geometry>
      <material name="black"/>
    </visual>
    <collision>
      <origin rpy="0 0 0" xyz="0 0 0"/>
      <geometry>
        <mesh filename="package://jetarm_6dof_description/meshes/gripper/l_link.stl"/>
      </geometry>
    </collision>
  </link>
  <joint name="l_joint" type="revolute">
    <origin rpy="0 0 1.5707963267948966" xyz="-0.0073115 0.01400015081 0.027008 "/>
    <parent link="gripper_servo_link"/>
    <child link="l_link"/>
    <axis xyz="0 -1 0"/>
    <limit effort="1000" lower="-1.57" upper="1.57" velocity="2"/>
    <mimic joint="r_joint" multiplier="-1" offset="0"/>
  </joint>
  <link name="r_in_link">
    <inertial>
      <origin rpy="0 0 0" xyz="-1.7319E-09 -0.006 0.0145"/>
      <mass value="0.00001"/>
      <inertia ixx="10" ixy="0" ixz="0" iyy="10" iyz="0" izz="10"/>
    </inertial>
    <visual>
      <origin rpy="0 0 0" xyz="0 0 0"/>
      <geometry>
        <mesh filename="package://jetarm_6dof_description/meshes/gripper/r_in_link.stl"/>
      </geometry>
      <material name="black"/>
    </visual>
    <collision>
      <origin rpy="0 0 0" xyz="0 0 0"/>
      <geometry>
        <mesh filename="package://jetarm_6dof_description/meshes/gripper/r_in_link.stl"/>
      </geometry>
    </collision>
  </link>
  <joint name="r_in_joint" type="revolute">
    <origin rpy="0 0 1.5707963267948966" xyz="-0.0065253 -0.0075039 0.04599137946"/>
    <parent link="gripper_servo_link"/>
    <child link="r_in_link"/>
    <axis xyz="0 1 0"/>
    <mimic joint="r_joint" multiplier="-1" offset="0"/>
    <limit effort="1000" lower="-1.57" upper="1.57" velocity="2"/>
  </joint>
  <link name="r_out_link">
    <inertial>
      <origin rpy="0 0 0" xyz="-0.0013784 -0.0060519 0.0096418"/>
      <mass value="0.00001"/>
      <inertia ixx="10" ixy="0" ixz="0" iyy="10" iyz="0" izz="10"/>
    </inertial>
    <visual>
      <origin rpy="0 0 0" xyz="0 0 0"/>
      <geometry>
        <mesh filename="package://jetarm_6dof_description/meshes/gripper/r_out_link.stl"/>
      </geometry>
      <material name="black"/>
    </visual>
    <collision>
      <origin rpy="0 0 0" xyz="0 0 0"/>
      <geometry>
        <mesh filename="package://jetarm_6dof_description/meshes/gripper/r_out_link.stl"/>
      </geometry>
    </collision>
  </link>
  <joint name="r_out_joint" type="revolute">
    <origin rpy="0 0 0" xyz="0 0 0.029"/>
    <parent link="r_in_link"/>
    <child link="r_out_link"/>
    <axis xyz="0 1 0"/>
    <mimic joint="r_joint" multiplier="1" offset="0"/>
    <limit effort="1000" lower="-1.57" upper="1.57" velocity="2"/>
  </joint>
  <link name="l_in_link">
    <inertial>
      <origin rpy="0 0 0" xyz="-1.7319E-09 -0.006 0.0145"/>
      <mass value="0.00001"/>
      <inertia ixx="10" ixy="0" ixz="0" iyy="10" iyz="0" izz="10"/>
    </inertial>
    <visual>
      <origin rpy="0 0 0" xyz="0 0 0"/>
      <geometry>
        <mesh filename="package://jetarm_6dof_description/meshes/gripper/l_in_link.stl"/>
      </geometry>
      <material name="black"/>
    </visual>
    <collision>
      <origin rpy="0 0 0" xyz="0 0 0"/>
      <geometry>
        <mesh filename="package://jetarm_6dof_description/meshes/gripper/l_in_link.stl"/>
      </geometry>
    </collision>
  </link>
  <joint name="l_in_joint" type="revolute">
    <origin rpy="0 0 1.5707963267948966" xyz="-0.0065053 0.0075039 0.04599108168"/>
    <parent link="gripper_servo_link"/>
    <child link="l_in_link"/>
    <axis xyz="0 -1 0"/>
    <mimic joint="r_joint" multiplier="-1" offset="0"/>
    <limit effort="1000" lower="-1.57" upper="1.57" velocity="2"/>
  </joint>
  <link name="l_out_link">
    <inertial>
      <origin rpy="0 0 0" xyz="0.0013784 -0.0060519 0.0096418"/>
      <mass value="0.00001"/>
      <inertia ixx="10" ixy="0" ixz="0" iyy="10" iyz="0" izz="10"/>
    </inertial>
    <visual>
      <origin rpy="0 0 0" xyz="0 0 0"/>
      <geometry>
        <mesh filename="package://jetarm_6dof_description/meshes/gripper/l_out_link.stl"/>
      </geometry>
      <material name="black"/>
    </visual>
    <collision>
      <origin rpy="0 0 0" xyz="0 0 0"/>
      <geometry>
        <mesh filename="package://jetarm_6dof_description/meshes/gripper/l_out_link.stl"/>
      </geometry>
    </collision>
  </link>
  <joint name="l_out_joint" type="revolute">
    <origin rpy="0 0 0" xyz="0 0 0.029"/>
    <parent link="l_in_link"/>
    <child link="l_out_link"/>
    <axis xyz="0 -1 0"/>
    <mimic joint="r_joint" multiplier="1" offset="0"/>
    <limit effort="1000" lower="-1.57" upper="1.57" velocity="2"/>
  </joint>
  <!-- ros_control plugin -->
  <gazebo>
    <plugin filename="libgazebo_ros_control.so" name="gazebo_ros_control">
      <robotNamespace>/jetarm</robotNamespace>
      <robotSimType>gazebo_ros_control/DefaultRobotHWSim</robotSimType>
      <legacyModeNS>true</legacyModeNS>
    </plugin>
  </gazebo>
  <gazebo reference="link1">
    <kp>0</kp>
    <kd>0</kd>
    <mu1>1</mu1>
    <mu2>1</mu2>
    <minDepth>0.000</minDepth>
    <material>Gazebo/Grass</material>
  </gazebo>
  <gazebo reference="link2">
    <kp>0</kp>
    <kd>0</kd>
    <mu1>1</mu1>
    <mu2>1</mu2>
    <minDepth>0.000</minDepth>
    <material>Gazebo/Grass</material>
  </gazebo>
  <gazebo reference="link3">
    <kp>0</kp>
    <kd>0</kd>
    <mu1>1</mu1>
    <mu2>1</mu2>
    <minDepth>0.000</minDepth>
    <material>Gazebo/Grass</material>
  </gazebo>
  <gazebo reference="link4">
    <kp>0</kp>
    <kd>0</kd>
    <mu1>1</mu1>
    <mu2>1</mu2>
    <minDepth>0.000</minDepth>
    <material>Gazebo/Grass</material>
  </gazebo>
  <gazebo reference="link5">
    <kp>0</kp>
    <kd>0</kd>
    <mu1>1</mu1>
    <mu2>1</mu2>
    <minDepth>0.000</minDepth>
    <material>Gazebo/Grass</material>
  </gazebo>
  <gazebo reference="r_link">
    <kp>1e15</kp>
    <kd>1e13</kd>
    <mu1>1.0</mu1>
    <mu2>1.0</mu2>
    <minDepth>0.0002</minDepth>
    <material>Gazebo/Black</material>
  </gazebo>
  <gazebo reference="l_link">
    <material>Gazebo/Black</material>
  </gazebo>
  <gazebo reference="l_in_link">
    <material>Gazebo/Black</material>
  </gazebo>
  <gazebo reference="l_out_link">
    <material>Gazebo/Black</material>
  </gazebo>
  <gazebo reference="r_in_link">
    <material>Gazebo/Black</material>
  </gazebo>
  <gazebo reference="r_out_link">
    <material>Gazebo/Black</material>
  </gazebo>
  <gazebo reference="base_link">
    <material>Gazebo/Black</material>
  </gazebo>
  <gazebo reference="gripper_servo_link">
    <material>Gazebo/Black</material>
  </gazebo>
  <transmission name="joint1_trans">
    <type>transmission_interface/SimpleTransmission</type>
    <joint name="joint1">
      <hardwareInterface>hardware_interface/EffortJointInterface</hardwareInterface>
    </joint>
    <actuator name="joint1_motor">
      <hardwareInterface>hardware_interface/EffortJointInterface</hardwareInterface>
      <mechanicalReduction>1</mechanicalReduction>
    </actuator>
  </transmission>
  <transmission name="joint2_trans">
    <type>transmission_interface/SimpleTransmission</type>
    <joint name="joint2">
      <hardwareInterface>hardware_interface/EffortJointInterface</hardwareInterface>
    </joint>
    <actuator name="joint2_motor">
      <hardwareInterface>hardware_interface/EffortJointInterface</hardwareInterface>
      <mechanicalReduction>1</mechanicalReduction>
    </actuator>
  </transmission>
  <transmission name="joint3_trans">
    <type>transmission_interface/SimpleTransmission</type>
    <joint name="joint3">
      <hardwareInterface>hardware_interface/EffortJointInterface</hardwareInterface>
    </joint>
    <actuator name="joint3_motor">
      <hardwareInterface>hardware_interface/EffortJointInterface</hardwareInterface>
      <mechanicalReduction>1</mechanicalReduction>
    </actuator>
  </transmission>
  <transmission name="joint4_trans">
    <type>transmission_interface/SimpleTransmission</type>
    <joint name="joint4">
      <hardwareInterface>hardware_interface/EffortJointInterface</hardwareInterface>
    </joint>
    <actuator name="joint4_motor">
      <hardwareInterface>hardware_interface/EffortJointInterface</hardwareInterface>
      <mechanicalReduction>1</mechanicalReduction>
    </actuator>
  </transmission>
  <transmission name="joint5_trans">
    <type>transmission_interface/SimpleTransmission</type>
    <joint name="joint5">
      <hardwareInterface>hardware_interface/EffortJointInterface</hardwareInterface>
    </joint>
    <actuator name="joint5_motor">
      <hardwareInterface>hardware_interface/EffortJointInterface</hardwareInterface>
      <mechanicalReduction>1</mechanicalReduction>
    </actuator>
  </transmission>
  <transmission name="r_joint_trans">
    <type>transmission_interface/SimpleTransmission</type>
    <joint name="r_joint">
      <hardwareInterface>hardware_interface/EffortJointInterface</hardwareInterface>
    </joint>
    <actuator name="r_joint_motor">
      <hardwareInterface>hardware_interface/EffortJointInterface</hardwareInterface>
      <mechanicalReduction>1</mechanicalReduction>
    </actuator>
  </transmission>
  <!-- <xacro:jetarm_ros2_control name="jetarm" prefix="$(arg prefix)" /> -->
</robot>
